<?xml version="1.0" encoding="utf-8"?>
<!-- This URDF was automatically created by SolidWorks to URDF Exporter! Originally created by Stephen Brawner (brawner@gmail.com) 
     Commit Version: 1.6.0-4-g7f85cfe  Build Version: 1.6.7995.38578
     For more information, please see http://wiki.ros.org/sw_urdf_exporter -->
<robot
  name="ASSEM 2">
  <link
    name="base_link">
    <inertial>
      <origin
        xyz="0 1.38777878078145E-17 -0.04"
        rpy="0 0 0" />
      <mass
        value="0.15707963267949" />
      <inertia
        ixx="0.000391062835524979"
        ixy="6.21980377065526E-36"
        ixz="-9.88120452211026E-36"
        iyy="0.00039106283552498"
        iyz="6.48862588558017E-36"
        izz="0.000614574062858504" />
    </inertial>
    <visual>
      <origin
        xyz="0 0 0"
        rpy="0 0 0" />
      <geometry>
        <mesh
          filename="package://ASSEM 2/meshes/base_link.STL" />
      </geometry>
      <material
        name="">
        <color
          rgba="0.792156862745098 0.819607843137255 0.933333333333333 1" />
      </material>
    </visual>
    <collision>
      <origin
        xyz="0 0 0"
        rpy="0 0 0" />
      <geometry>
        <mesh
          filename="package://ASSEM 2/meshes/base_link.STL" />
      </geometry>
    </collision>
  </link>
  <link
    name="link1">
    <inertial>
      <origin
        xyz="0.00277146259382868 0.000977617047691573 -0.0392275940929765"
        rpy="0 0 0" />
      <mass
        value="0.10392584627471" />
      <inertia
        ixx="8.06918285221046E-05"
        ixy="-2.30972045071663E-07"
        ixz="1.9180114960661E-06"
        iyy="7.3013450070366E-05"
        iyz="2.74033815861124E-07"
        izz="0.000130206094147028" />
    </inertial>
    <visual>
      <origin
        xyz="0 0 0"
        rpy="0 0 0" />
      <geometry>
        <mesh
          filename="package://ASSEM 2/meshes/link1.STL" />
      </geometry>
      <material
        name="">
        <color
          rgba="0.792156862745098 0.819607843137255 0.933333333333333 1" />
      </material>
    </visual>
    <collision>
      <origin
        xyz="0 0 0"
        rpy="0 0 0" />
      <geometry>
        <mesh
          filename="package://ASSEM 2/meshes/link1.STL" />
      </geometry>
    </collision>
  </link>
  <joint
    name="joint1"
    type="revolute">
    <origin
      xyz="0 0 -0.065295"
      rpy="0 0 0" />
    <parent
      link="base_link" />
    <child
      link="link1" />
    <axis
      xyz="0 0 -1" />
    <limit
      lower="0"
      upper="0"
      effort="0"
      velocity="0" />
  </joint>
  <link
    name="link2">
    <inertial>
      <origin
        xyz="0.0403015509937278 -0.0403015509937268 0.0815648422319146"
        rpy="0 0 0" />
      <mass
        value="0.0258099114254626" />
      <inertia
        ixx="1.91418266297321E-05"
        ixy="4.72708625206505E-06"
        ixz="-5.50219404184871E-21"
        iyy="1.91418266297323E-05"
        iyz="5.27278066883589E-21"
        izz="1.12484016319642E-05" />
    </inertial>
    <visual>
      <origin
        xyz="0 0 0"
        rpy="0 0 0" />
      <geometry>
        <mesh
          filename="package://ASSEM 2/meshes/link2.STL" />
      </geometry>
      <material
        name="">
        <color
          rgba="0.792156862745098 0.819607843137255 0.933333333333333 1" />
      </material>
    </visual>
    <collision>
      <origin
        xyz="0 0 0"
        rpy="0 0 0" />
      <geometry>
        <mesh
          filename="package://ASSEM 2/meshes/link2.STL" />
      </geometry>
    </collision>
  </link>
  <joint
    name="joint2"
    type="revolute">
    <origin
      xyz="0.014245 0.081565 -0.077949"
      rpy="1.5708 0 0" />
    <parent
      link="link1" />
    <child
      link="link2" />
    <axis
      xyz="0 0 -1" />
    <limit
      lower="-3.14"
      upper="3.14"
      effort="0.8357"
      velocity="5.235" />
  </joint>
  <link
    name="link3">
    <inertial>
      <origin
        xyz="0.0323024454898762 0.0330392074388971 0.0830187996879243"
        rpy="0 0 0" />
      <mass
        value="0.0698780273763374" />
      <inertia
        ixx="3.55297243478853E-05"
        ixy="-1.12773149423438E-05"
        ixz="2.33341441598977E-07"
        iyy="3.59517146165329E-05"
        iyz="2.72019095535887E-07"
        izz="2.75333599213435E-05" />
    </inertial>
    <visual>
      <origin
        xyz="0 0 0"
        rpy="0 0 0" />
      <geometry>
        <mesh
          filename="package://ASSEM 2/meshes/link3.STL" />
      </geometry>
      <material
        name="">
        <color
          rgba="0.792156862745098 0.819607843137255 0.933333333333333 1" />
      </material>
    </visual>
    <collision>
      <origin
        xyz="0 0 0"
        rpy="0 0 0" />
      <geometry>
        <mesh
          filename="package://ASSEM 2/meshes/link3.STL" />
      </geometry>
    </collision>
  </link>
  <joint
    name="joint3"
    type="revolute">
    <origin
      xyz="0.0806066375213615 -0.0806066375213595 0"
      rpy="0 0 0" />
    <parent
      link="link2" />
    <child
      link="link3" />
    <axis
      xyz="0 0 -1" />
    <limit
      lower="-3.14"
      upper="3.14"
      effort="0.83357"
      velocity="5.235" />
  </joint>
  <link
    name="link4">
    <inertial>
      <origin
        xyz="0.0315375369846145 0.000942829333490151 0.0215178892714787"
        rpy="0 0 0" />
      <mass
        value="0.0770925872338047" />
      <inertia
        ixx="1.83587552242031E-05"
        ixy="3.43021070226104E-06"
        ixz="4.36773633370026E-07"
        iyy="3.62874257481099E-05"
        iyz="4.19679017550082E-08"
        izz="3.35923516563554E-05" />
    </inertial>
    <visual>
      <origin
        xyz="0 0 0"
        rpy="0 0 0" />
      <geometry>
        <mesh
          filename="package://ASSEM 2/meshes/link4.STL" />
      </geometry>
      <material
        name="">
        <color
          rgba="0.792156862745098 0.819607843137255 0.933333333333333 1" />
      </material>
    </visual>
    <collision>
      <origin
        xyz="0 0 0"
        rpy="0 0 0" />
      <geometry>
        <mesh
          filename="package://ASSEM 2/meshes/link4.STL" />
      </geometry>
    </collision>
  </link>
  <joint
    name="joint4"
    type="revolute">
    <origin
      xyz="0.117062359119247 0.115053071254504 0.0592138803375897"
      rpy="0 0 0" />
    <parent
      link="link3" />
    <child
      link="link4" />
    <axis
      xyz="0 0 -1" />
    <limit
      lower="-3.14"
      upper="3.14"
      effort="0.83357"
      velocity="5.235" />
  </joint>
  <link
    name="gripkiri">
    <inertial>
      <origin
        xyz="0.014682818458544 -0.000406177253536102 -0.0218916024198144"
        rpy="0 0 0" />
      <mass
        value="0.00468228410417343" />
      <inertia
        ixx="2.35592289956318E-07"
        ixy="-2.02600157549245E-08"
        ixz="-1.45292461833238E-22"
        iyy="2.06790380943813E-06"
        iyz="-6.46592022391514E-24"
        izz="2.29101000844998E-06" />
    </inertial>
    <visual>
      <origin
        xyz="0 0 0"
        rpy="0 0 0" />
      <geometry>
        <mesh
          filename="package://ASSEM 2/meshes/gripkiri.STL" />
      </geometry>
      <material
        name="">
        <color
          rgba="0.792156862745098 0.819607843137255 0.933333333333333 1" />
      </material>
    </visual>
    <collision>
      <origin
        xyz="0 0 0"
        rpy="0 0 0" />
      <geometry>
        <mesh
          filename="package://ASSEM 2/meshes/gripkiri.STL" />
      </geometry>
    </collision>
  </link>
  <joint
    name="gripkiri"
    type="revolute">
    <origin
      xyz="0.084296005674642 0.0435030263892294 0.0395009618943247"
      rpy="-1.5707963267949 0 -0.0309604369909043" />
    <parent
      link="link4" />
    <child
      link="gripkiri" />
    <axis
      xyz="0 0 -1" />
    <limit
      lower="-3.14"
      upper="3.14"
      effort="0.21575"
      velocity="10.47" />
  </joint>
  <link
    name="endkiri">
    <inertial>
      <origin
        xyz="-0.287972996648998 0.00178516586371753 -0.0217965070142749"
        rpy="0 0 0" />
      <mass
        value="0.443150595663642" />
      <inertia
        ixx="0.00196078344559034"
        ixy="-1.30067282999552E-05"
        ixz="0.000876779035566921"
        iyy="0.00646286226177141"
        iyz="-8.01893940297324E-06"
        izz="0.00536100266374495" />
    </inertial>
    <visual>
      <origin
        xyz="0 0 0"
        rpy="0 0 0" />
      <geometry>
        <mesh
          filename="package://ASSEM 2/meshes/endkiri.STL" />
      </geometry>
      <material
        name="">
        <color
          rgba="1 1 1 1" />
      </material>
    </visual>
    <collision>
      <origin
        xyz="0 0 0"
        rpy="0 0 0" />
      <geometry>
        <mesh
          filename="package://ASSEM 2/meshes/endkiri.STL" />
      </geometry>
    </collision>
  </link>
  <joint
    name="endkiri"
    type="fixed">
    <origin
      xyz="0.0657309702758853 0.0155256915901593 -0.0198916024198144"
      rpy="0 0 0" />
    <parent
      link="gripkiri" />
    <child
      link="endkiri" />
    <axis
      xyz="0 0 0" />
  </joint>
  <link
    name="gripkanan">
    <inertial>
      <origin
        xyz="0.0148063042759796 0.000414028412186004 -0.0218862224173077"
        rpy="0 0 0" />
      <mass
        value="0.00468228410417343" />
      <inertia
        ixx="2.35570244923864E-07"
        ixy="1.9237317523319E-08"
        ixz="-5.70220168567931E-23"
        iyy="2.06792585447058E-06"
        iyz="-1.23541639058095E-24"
        izz="2.29101000844998E-06" />
    </inertial>
    <visual>
      <origin
        xyz="0 0 0"
        rpy="0 0 0" />
      <geometry>
        <mesh
          filename="package://ASSEM 2/meshes/gripkanan.STL" />
      </geometry>
      <material
        name="">
        <color
          rgba="0.792156862745098 0.819607843137255 0.933333333333333 1" />
      </material>
    </visual>
    <collision>
      <origin
        xyz="0 0 0"
        rpy="0 0 0" />
      <geometry>
        <mesh
          filename="package://ASSEM 2/meshes/gripkanan.STL" />
      </geometry>
    </collision>
  </link>
  <joint
    name="gripkanan"
    type="revolute">
    <origin
      xyz="0.0841222076722561 0.0435030263892294 0.00370096189432474"
      rpy="-1.5707963267949 0 -0.0309604369909049" />
    <parent
      link="link4" />
    <child
      link="gripkanan" />
    <axis
      xyz="0 0 -1" />
    <limit
      lower="-3.14"
      upper="3.14"
      effort="0.21575"
      velocity="10.47" />
  </joint>
  <link
    name="endkanan">
    <inertial>
      <origin
        xyz="-0.287253246196077 -0.00299979659536508 -0.043701528570305"
        rpy="0 0 0" />
      <mass
        value="0.443150595663642" />
      <inertia
        ixx="0.00196078344559034"
        ixy="-1.30067282999552E-05"
        ixz="0.000876779035566919"
        iyy="0.00646286226177141"
        iyz="-8.0189394029734E-06"
        izz="0.00536100266374495" />
    </inertial>
    <visual>
      <origin
        xyz="0 0 0"
        rpy="0 0 0" />
      <geometry>
        <mesh
          filename="package://ASSEM 2/meshes/endkanan.STL" />
      </geometry>
      <material
        name="">
        <color
          rgba="1 1 1 1" />
      </material>
    </visual>
    <collision>
      <origin
        xyz="0 0 0"
        rpy="0 0 0" />
      <geometry>
        <mesh
          filename="package://ASSEM 2/meshes/endkanan.STL" />
      </geometry>
    </collision>
  </link>
  <joint
    name="endkanan"
    type="fixed">
    <origin
      xyz="0.0651849345350827 -0.0154893459507581 0.00201879913872238"
      rpy="0 0 0" />
    <parent
      link="gripkanan" />
    <child
      link="endkanan" />
    <axis
      xyz="0 0 0" />
  </joint>
</robot>